<sdf version='1.7'>
  <world name='default'>
    <light name='sun' type='directional'>
      <cast_shadows>1</cast_shadows>
      <pose>0 0 10 0 -0 0</pose>
      <diffuse>0.8 0.8 0.8 1</diffuse>
      <specular>0.2 0.2 0.2 1</specular>
      <attenuation>
        <range>1000</range>
        <constant>0.9</constant>
        <linear>0.01</linear>
        <quadratic>0.001</quadratic>
      </attenuation>
      <direction>-0.5 0.1 -0.9</direction>
      <spot>
        <inner_angle>0</inner_angle>
        <outer_angle>0</outer_angle>
        <falloff>0</falloff>
      </spot>
    </light>
    <model name='ground_plane'>
      <static>1</static>
      <link name='link'>
        <collision name='collision'>
          <geometry>
            <plane>
              <normal>0 0 1</normal>
              <size>100 100</size>
            </plane>
          </geometry>
          <surface>
            <friction>
              <ode>
                <mu>100</mu>
                <mu2>50</mu2>
              </ode>
              <torsional>
                <ode/>
              </torsional>
            </friction>
            <contact>
              <ode/>
            </contact>
            <bounce/>
          </surface>
          <max_contacts>10</max_contacts>
        </collision>
        <visual name='visual'>
          <cast_shadows>0</cast_shadows>
          <geometry>
            <plane>
              <normal>0 0 1</normal>
              <size>100 100</size>
            </plane>
          </geometry>
          <material>
            <script>
              <uri>file://media/materials/scripts/gazebo.material</uri>
              <name>Gazebo/Grey</name>
            </script>
          </material>
        </visual>
        <self_collide>0</self_collide>
        <enable_wind>0</enable_wind>
        <kinematic>0</kinematic>
      </link>
    </model>
    <gravity>0 0 -9.8</gravity>
    <magnetic_field>6e-06 2.3e-05 -4.2e-05</magnetic_field>
    <atmosphere type='adiabatic'/>
    <physics type='ode'>
      <max_step_size>0.001</max_step_size>
      <real_time_factor>1</real_time_factor>
      <real_time_update_rate>1000</real_time_update_rate>
    </physics>
    <scene>
      <ambient>0.4 0.4 0.4 1</ambient>
      <background>0.7 0.7 0.7 1</background>
      <shadows>1</shadows>
    </scene>
    <audio>
      <device>default</device>
    </audio>
    <wind/>
    <spherical_coordinates>
      <surface_model>EARTH_WGS84</surface_model>
      <latitude_deg>0</latitude_deg>
      <longitude_deg>0</longitude_deg>
      <elevation>0</elevation>
      <heading_deg>0</heading_deg>
    </spherical_coordinates>
    <model name='my_bot'>
      <link name='base_footprint'>
        <inertial>
          <pose>0 0 4.6e-05 0 -0 0</pose>
          <mass>24.74</mass>
          <inertia>
            <ixx>0.208466</ixx>
            <ixy>0</ixy>
            <ixz>0</ixz>
            <iyy>1.19284</iyy>
            <iyz>0</iyz>
            <izz>1.35938</izz>
          </inertia>
        </inertial>
        <collision name='base_footprint_fixed_joint_lump__chassis_link_collision'>
          <pose>0 0 0 0 -0 0</pose>
          <geometry>
            <mesh>
              <scale>1 1 1</scale>
              <uri>model://yahboom_bot_1/meshes/Ackermann/base_link.STL</uri>
            </mesh>
          </geometry>
          <surface>
            <contact>
              <ode/>
            </contact>
            <friction>
              <ode>
                <mu>0.5</mu>
                <mu2>0.5</mu2>
              </ode>
              <torsional>
                <ode/>
              </torsional>
            </friction>
            <bounce/>
          </surface>
          <max_contacts>10</max_contacts>
        </collision>
        <collision name='base_footprint_fixed_joint_lump__laser_link_collision_1'>
          <pose>0 0 0.115 0 0 -3.14159</pose>
          <geometry>
            <cylinder>
              <length>0.02</length>
              <radius>0.02</radius>
            </cylinder>
          </geometry>
          <surface>
            <contact>
              <ode/>
            </contact>
            <friction>
              <ode/>
              <torsional>
                <ode/>
              </torsional>
            </friction>
            <bounce/>
          </surface>
          <max_contacts>10</max_contacts>
        </collision>
        <visual name='base_footprint_fixed_joint_lump__chassis_link_visual'>
          <pose>0 0 0 0 -0 0</pose>
          <geometry>
            <mesh>
              <scale>1 1 1</scale>
              <uri>model://yahboom_bot_1/meshes/Ackermann/base_link.STL</uri>
            </mesh>
          </geometry>
          <material>
            <script>
              <name>Gazebo/White</name>
              <uri>file://media/materials/scripts/gazebo.material</uri>
            </script>
          </material>
        </visual>
        <visual name='base_footprint_fixed_joint_lump__laser_link_visual_1'>
          <pose>0 0 0.115 0 0 -3.14159</pose>
          <geometry>
            <cylinder>
              <length>0.02</length>
              <radius>0.02</radius>
            </cylinder>
          </geometry>
          <material>
            <script>
              <name>Gazebo/Red</name>
              <uri>file://media/materials/scripts/gazebo.material</uri>
            </script>
          </material>
        </visual>
        <sensor name='laser' type='ray'>
          <update_rate>10</update_rate>
          <visualize>1</visualize>
          <ray>
            <scan>
              <horizontal>
                <samples>90</samples>
                <min_angle>-3.14159</min_angle>
                <max_angle>3.14159</max_angle>
                <resolution>1</resolution>
              </horizontal>
              <vertical>
                <samples>1</samples>
                <min_angle>0</min_angle>
                <max_angle>0</max_angle>
              </vertical>
            </scan>
            <range>
              <min>0.1</min>
              <max>5</max>
            </range>
          </ray>
          <plugin name='laser_controller' filename='libgazebo_ros_ray_laser.so'>
            <ros>
              <argument>~/out:=scan</argument>
            </ros>
            <output_type>sensor_msgs/LaserScan</output_type>
            <frame_name>laser_link</frame_name>
          </plugin>
          <pose>0 0 0.115 0 -0 -3.14159</pose>
        </sensor>
        <self_collide>0</self_collide>
        <enable_wind>0</enable_wind>
        <kinematic>0</kinematic>
      </link>
      <joint name='fr_left_steer_joint' type='revolute'>
        <pose relative_to='base_footprint'>0.11922 0.065 0.0262 0 -0 0</pose>
        <parent>base_footprint</parent>
        <child>fr_left_steer_link</child>
        <axis>
          <xyz>0 0 1</xyz>
          <limit>
            <lower>-0.6</lower>
            <upper>0.6</upper>
            <effort>-1</effort>
            <velocity>-1</velocity>
          </limit>
          <dynamics>
            <spring_reference>0</spring_reference>
            <spring_stiffness>0</spring_stiffness>
          </dynamics>
        </axis>
      </joint>
      <link name='fr_left_steer_link'>
        <pose relative_to='fr_left_steer_joint'>0 0 0 0 -0 0</pose>
        <inertial>
          <pose>-0.004468 0.00312 -0.014101 0 -0 0</pose>
          <mass>0.01</mass>
          <inertia>
            <ixx>6.53333e-05</ixx>
            <ixy>0</ixy>
            <ixz>0</ixz>
            <iyy>6.53333e-05</iyy>
            <iyz>0</iyz>
            <izz>9.8e-05</izz>
          </inertia>
        </inertial>
        <visual name='fr_left_steer_link_visual'>
          <pose>0 0 0 0 -0 0</pose>
          <geometry>
            <mesh>
              <scale>1 1 1</scale>
              <uri>model://yahboom_bot_1/meshes/Ackermann/front_left_steer.STL</uri>
            </mesh>
          </geometry>
        </visual>
        <self_collide>0</self_collide>
        <enable_wind>0</enable_wind>
        <kinematic>0</kinematic>
      </link>
      <joint name='fr_left_wheel_joint' type='revolute'>
        <pose relative_to='fr_left_steer_link'>0.000229 0.0228 -0.0141 0 0 -0.010042</pose>
        <parent>fr_left_steer_link</parent>
        <child>fr_left_wheel_link</child>
        <axis>
          <xyz>0 1 0</xyz>
          <limit>
            <effort>200</effort>
            <velocity>-1</velocity>
            <lower>-1e+16</lower>
            <upper>1e+16</upper>
          </limit>
          <dynamics>
            <damping>0.5</damping>
            <friction>0.8</friction>
            <spring_reference>0</spring_reference>
            <spring_stiffness>0</spring_stiffness>
          </dynamics>
        </axis>
      </joint>
      <link name='fr_left_wheel_link'>
        <pose relative_to='fr_left_wheel_joint'>0 0 0 0 -0 0</pose>
        <inertial>
          <pose>-0 -0.004812 0 0 -0 0</pose>
          <mass>3</mass>
          <inertia>
            <ixx>0.0196</ixx>
            <ixy>0</ixy>
            <ixz>0</ixz>
            <iyy>0.0196</iyy>
            <iyz>0</iyz>
            <izz>0.0294</izz>
          </inertia>
        </inertial>
        <collision name='fr_left_wheel_link_collision'>
          <pose>0 0 0 1.5708 -0 0</pose>
          <geometry>
            <cylinder>
              <length>0.022</length>
              <radius>0.035</radius>
            </cylinder>
          </geometry>
          <surface>
            <contact>
              <ode/>
            </contact>
            <friction>
              <ode>
                <mu>1</mu>
                <mu2>1</mu2>
              </ode>
              <torsional>
                <ode/>
              </torsional>
            </friction>
            <bounce/>
          </surface>
          <max_contacts>10</max_contacts>
        </collision>
        <visual name='fr_left_wheel_link_visual'>
          <pose>0 0 0 3.14159 -0 0</pose>
          <geometry>
            <mesh>
              <scale>1 1 1</scale>
              <uri>model://yahboom_bot_1/meshes/Ackermann/back_right_link.STL</uri>
            </mesh>
          </geometry>
          <material>
            <script>
              <name>Gazebo/Grey</name>
              <uri>file://media/materials/scripts/gazebo.material</uri>
            </script>
          </material>
        </visual>
        <self_collide>0</self_collide>
        <enable_wind>0</enable_wind>
        <kinematic>0</kinematic>
      </link>
      <joint name='fr_right_steer_joint' type='revolute'>
        <pose relative_to='base_footprint'>0.11922 -0.065 0.0242 0 -0 0</pose>
        <parent>base_footprint</parent>
        <child>fr_right_steer_link</child>
        <axis>
          <xyz>0 0 1</xyz>
          <limit>
            <lower>-0.6</lower>
            <upper>0.6</upper>
            <effort>-1</effort>
            <velocity>-1</velocity>
          </limit>
          <dynamics>
            <spring_reference>0</spring_reference>
            <spring_stiffness>0</spring_stiffness>
          </dynamics>
        </axis>
      </joint>
      <link name='fr_right_steer_link'>
        <pose relative_to='fr_right_steer_joint'>0 0 0 0 -0 0</pose>
        <inertial>
          <pose>-0.004539 -0.003016 -0.012099 0 -0 0</pose>
          <mass>0.01</mass>
          <inertia>
            <ixx>6.53333e-05</ixx>
            <ixy>0</ixy>
            <ixz>0</ixz>
            <iyy>6.53333e-05</iyy>
            <iyz>0</iyz>
            <izz>9.8e-05</izz>
          </inertia>
        </inertial>
        <visual name='fr_right_steer_link_visual'>
          <pose>0 0 0 0 -0 3.14159</pose>
          <geometry>
            <mesh>
              <scale>1 1 1</scale>
              <uri>model://yahboom_bot_1/meshes/Ackermann/front_left_steer.STL</uri>
            </mesh>
          </geometry>
        </visual>
        <self_collide>0</self_collide>
        <enable_wind>0</enable_wind>
        <kinematic>0</kinematic>
      </link>
      <joint name='fr_right_wheel_joint' type='revolute'>
        <pose relative_to='fr_right_steer_link'>-0.000257 -0.019549 -0.0121 0 0 -0.013126</pose>
        <parent>fr_right_steer_link</parent>
        <child>fr_right_wheel_link</child>
        <axis>
          <xyz>0 1 0</xyz>
          <limit>
            <effort>200</effort>
            <velocity>-1</velocity>
            <lower>-1e+16</lower>
            <upper>1e+16</upper>
          </limit>
          <dynamics>
            <damping>0.5</damping>
            <friction>0.8</friction>
            <spring_reference>0</spring_reference>
            <spring_stiffness>0</spring_stiffness>
          </dynamics>
        </axis>
      </joint>
      <link name='fr_right_wheel_link'>
        <pose relative_to='fr_right_wheel_joint'>0 0 0 0 -0 0</pose>
        <inertial>
          <pose>0 0.001562 -0 0 -0 0</pose>
          <mass>3</mass>
          <inertia>
            <ixx>0.0196</ixx>
            <ixy>0</ixy>
            <ixz>0</ixz>
            <iyy>0.0196</iyy>
            <iyz>0</iyz>
            <izz>0.0294</izz>
          </inertia>
        </inertial>
        <collision name='fr_right_wheel_link_collision'>
          <pose>0 0 0 1.5708 -0 0</pose>
          <geometry>
            <cylinder>
              <length>0.022</length>
              <radius>0.035</radius>
            </cylinder>
          </geometry>
          <surface>
            <contact>
              <ode/>
            </contact>
            <friction>
              <ode>
                <mu>1</mu>
                <mu2>1</mu2>
              </ode>
              <torsional>
                <ode/>
              </torsional>
            </friction>
            <bounce/>
          </surface>
          <max_contacts>10</max_contacts>
        </collision>
        <visual name='fr_right_wheel_link_visual'>
          <pose>0 0 0 0 -0 0</pose>
          <geometry>
            <mesh>
              <scale>1 1 1</scale>
              <uri>model://yahboom_bot_1/meshes/Ackermann/back_right_link.STL</uri>
            </mesh>
          </geometry>
          <material>
            <script>
              <name>Gazebo/Grey</name>
              <uri>file://media/materials/scripts/gazebo.material</uri>
            </script>
          </material>
        </visual>
        <self_collide>0</self_collide>
        <enable_wind>0</enable_wind>
        <kinematic>0</kinematic>
      </link>
      <joint name='re_left_wheel_joint' type='revolute'>
        <pose relative_to='base_footprint'>-0.11607 0.08425 0.0125 0 -0 0</pose>
        <parent>base_footprint</parent>
        <child>re_left_wheel_link</child>
        <axis>
          <xyz>0 1 0</xyz>
          <limit>
            <effort>70</effort>
            <velocity>-1</velocity>
            <lower>-1e+16</lower>
            <upper>1e+16</upper>
          </limit>
          <dynamics>
            <damping>0.5</damping>
            <friction>0.8</friction>
            <spring_reference>0</spring_reference>
            <spring_stiffness>0</spring_stiffness>
          </dynamics>
        </axis>
      </joint>
      <link name='re_left_wheel_link'>
        <pose relative_to='re_left_wheel_joint'>0 0 0 0 -0 0</pose>
        <inertial>
          <pose>-0 -0.001562 0 0 -0 0</pose>
          <mass>3</mass>
          <inertia>
            <ixx>0.0196</ixx>
            <ixy>0</ixy>
            <ixz>0</ixz>
            <iyy>0.0196</iyy>
            <iyz>0</iyz>
            <izz>0.0294</izz>
          </inertia>
        </inertial>
        <collision name='re_left_wheel_link_collision'>
          <pose>0 0 0 1.5708 -0 0</pose>
          <geometry>
            <cylinder>
              <length>0.022</length>
              <radius>0.035</radius>
            </cylinder>
          </geometry>
          <surface>
            <contact>
              <ode/>
            </contact>
            <friction>
              <ode>
                <mu>1</mu>
                <mu2>1</mu2>
              </ode>
              <torsional>
                <ode/>
              </torsional>
            </friction>
            <bounce/>
          </surface>
          <max_contacts>10</max_contacts>
        </collision>
        <visual name='re_left_wheel_link_visual'>
          <pose>0 0 0 3.14159 -0 0</pose>
          <geometry>
            <mesh>
              <scale>1 1 1</scale>
              <uri>model://yahboom_bot_1/meshes/Ackermann/back_right_link.STL</uri>
            </mesh>
          </geometry>
          <material>
            <script>
              <name>Gazebo/Grey</name>
              <uri>file://media/materials/scripts/gazebo.material</uri>
            </script>
          </material>
        </visual>
        <self_collide>0</self_collide>
        <enable_wind>0</enable_wind>
        <kinematic>0</kinematic>
      </link>
      <joint name='re_right_wheel_joint' type='revolute'>
        <pose relative_to='base_footprint'>-0.11607 -0.08425 0.0125 0 -0 0</pose>
        <parent>base_footprint</parent>
        <child>re_right_wheel_link</child>
        <axis>
          <xyz>0 1 0</xyz>
          <limit>
            <effort>70</effort>
            <velocity>-1</velocity>
            <lower>-1e+16</lower>
            <upper>1e+16</upper>
          </limit>
          <dynamics>
            <damping>0.5</damping>
            <friction>0.8</friction>
            <spring_reference>0</spring_reference>
            <spring_stiffness>0</spring_stiffness>
          </dynamics>
        </axis>
      </joint>
      <link name='re_right_wheel_link'>
        <pose relative_to='re_right_wheel_joint'>0 0 0 0 -0 0</pose>
        <inertial>
          <pose>0 0.001562 -0 0 -0 0</pose>
          <mass>3</mass>
          <inertia>
            <ixx>0.0196</ixx>
            <ixy>0</ixy>
            <ixz>0</ixz>
            <iyy>0.0196</iyy>
            <iyz>0</iyz>
            <izz>0.0294</izz>
          </inertia>
        </inertial>
        <collision name='re_right_wheel_link_collision'>
          <pose>0 0 0 1.5708 -0 0</pose>
          <geometry>
            <cylinder>
              <length>0.035</length>
              <radius>0.022</radius>
            </cylinder>
          </geometry>
          <surface>
            <contact>
              <ode/>
            </contact>
            <friction>
              <ode>
                <mu>1</mu>
                <mu2>1</mu2>
              </ode>
              <torsional>
                <ode/>
              </torsional>
            </friction>
            <bounce/>
          </surface>
          <max_contacts>10</max_contacts>
        </collision>
        <visual name='re_right_wheel_link_visual'>
          <pose>0 0 0 0 -0 0</pose>
          <geometry>
            <mesh>
              <scale>1 1 1</scale>
              <uri>model://yahboom_bot_1/meshes/Ackermann/back_right_link.STL</uri>
            </mesh>
          </geometry>
          <material>
            <script>
              <name>Gazebo/Grey</name>
              <uri>file://media/materials/scripts/gazebo.material</uri>
            </script>
          </material>
        </visual>
        <self_collide>0</self_collide>
        <enable_wind>0</enable_wind>
        <kinematic>0</kinematic>
      </link>
      <joint name='virtual_steering_wheel_joint' type='revolute'>
        <pose relative_to='base_footprint'>-0.32 0 0 0 -0 0</pose>
        <parent>base_footprint</parent>
        <child>virtual_steer_link</child>
        <axis>
          <xyz>-1 0 0</xyz>
          <limit>
            <lower>-3</lower>
            <upper>3</upper>
            <effort>200</effort>
            <velocity>20</velocity>
          </limit>
          <dynamics>
            <spring_reference>0</spring_reference>
            <spring_stiffness>0</spring_stiffness>
          </dynamics>
        </axis>
      </joint>
      <link name='virtual_steer_link'>
        <pose relative_to='virtual_steering_wheel_joint'>0 0 0 0 -0 0</pose>
        <inertial>
          <pose>0 0 0 0 -0 0</pose>
          <mass>0.001</mass>
          <inertia>
            <ixx>0</ixx>
            <ixy>0</ixy>
            <ixz>0</ixz>
            <iyy>0</iyy>
            <iyz>0</iyz>
            <izz>0</izz>
          </inertia>
        </inertial>
        <visual name='virtual_steer_link_visual'>
          <pose>0 0 0 0 -0 0</pose>
          <geometry>
            <box>
              <size>0.01 0.15 0.075</size>
            </box>
          </geometry>
          <material>
            <script>
              <name>Gazebo/Yellow</name>
              <uri>file://media/materials/scripts/gazebo.material</uri>
            </script>
          </material>
        </visual>
        <self_collide>0</self_collide>
        <enable_wind>0</enable_wind>
        <kinematic>0</kinematic>
      </link>
      <plugin name='gazebo_ros_joint_state_publisher' filename='libgazebo_ros_joint_state_publisher.so'>
        <update_rate>100</update_rate>
        <joint_name>fr_right_steer_joint</joint_name>
        <joint_name>fr_right_wheel_joint</joint_name>
        <joint_name>fr_left_steer_joint</joint_name>
        <joint_name>fr_left_wheel_joint</joint_name>
        <joint_name>re_right_wheel_joint</joint_name>
        <joint_name>re_left_wheel_joint</joint_name>
        <joint_name>virtual_steering_wheel_joint</joint_name>
      </plugin>
      <plugin name='gazebo_ros_joint_pose_trajectory' filename='libgazebo_ros_joint_pose_trajectory.so'>
        <update_rate>2</update_rate>
      </plugin>
      <static>0</static>
      <plugin name='gazebo_ackermann_drive' filename='libgazebo_ros_ackermann_drive.so'>
        <ros>
          <remapping>cmd_vel:=cmd_vel</remapping>
          <remapping>odom:=odom/bot</remapping>
          <remapping>distance:=distance/bot</remapping>
        </ros>
        <update_rate>100.0</update_rate>
        <front_left_joint>fr_left_wheel_joint</front_left_joint>
        <front_right_joint>fr_right_wheel_joint</front_right_joint>
        <rear_left_joint>re_left_wheel_joint</rear_left_joint>
        <rear_right_joint>re_right_wheel_joint</rear_right_joint>
        <left_steering_joint>fr_left_steer_joint</left_steering_joint>
        <right_steering_joint>fr_right_steer_joint</right_steering_joint>
        <steering_wheel_joint>virtual_steering_wheel_joint</steering_wheel_joint>
        <max_steer>0.383972</max_steer>
        <max_steering_angle>1.570796</max_steering_angle>
        <max_speed>20</max_speed>
        <left_steering_pid_gain>1500 0 1</left_steering_pid_gain>
        <left_steering_i_range>0 0</left_steering_i_range>
        <right_steering_pid_gain>1500 0 1</right_steering_pid_gain>
        <right_steering_i_range>0 0</right_steering_i_range>
        <linear_velocity_pid_gain>1500 0 1</linear_velocity_pid_gain>
        <linear_velocity_i_range>0 0</linear_velocity_i_range>
        <publish_odom>1</publish_odom>
        <publish_odom_tf>1</publish_odom_tf>
        <publish_wheel_tf>0</publish_wheel_tf>
        <publish_distance>1</publish_distance>
        <odometry_frame>odom</odometry_frame>
        <robot_base_frame>base_footprint</robot_base_frame>
      </plugin>
      <pose>0 0 0 0 -0 0</pose>
    </model>
    <model name='cardboard_box'>
      <pose>0.24722 0.899305 0.15 0 -0 0</pose>
      <link name='link'>
        <inertial>
          <mass>2</mass>
          <inertia>
            <ixx>0.0416667</ixx>
            <ixy>0</ixy>
            <ixz>0</ixz>
            <iyy>0.0566667</iyy>
            <iyz>0</iyz>
            <izz>0.0683333</izz>
          </inertia>
          <pose>0 0 0 0 -0 0</pose>
        </inertial>
        <collision name='collision'>
          <geometry>
            <box>
              <size>0.5 0.4 0.3</size>
            </box>
          </geometry>
          <surface>
            <friction>
              <ode>
                <mu>1</mu>
                <mu2>1</mu2>
              </ode>
              <torsional>
                <ode/>
              </torsional>
            </friction>
            <contact>
              <ode>
                <kp>1e+07</kp>
                <kd>1</kd>
                <min_depth>0.001</min_depth>
                <max_vel>0.1</max_vel>
              </ode>
            </contact>
            <bounce/>
          </surface>
          <max_contacts>10</max_contacts>
        </collision>
        <visual name='visual'>
          <pose>0 0 -0.15 0 -0 0</pose>
          <geometry>
            <mesh>
              <uri>model://cardboard_box/meshes/cardboard_box.dae</uri>
              <scale>1.25932 1.00745 0.755591</scale>
            </mesh>
          </geometry>
        </visual>
        <self_collide>0</self_collide>
        <enable_wind>0</enable_wind>
        <kinematic>0</kinematic>
      </link>
    </model>
    <model name='cardboard_box_0'>
      <pose>0.202515 -1.18824 0.15 0 -0 0</pose>
      <link name='link'>
        <inertial>
          <mass>2</mass>
          <inertia>
            <ixx>0.0416667</ixx>
            <ixy>0</ixy>
            <ixz>0</ixz>
            <iyy>0.0566667</iyy>
            <iyz>0</iyz>
            <izz>0.0683333</izz>
          </inertia>
          <pose>0 0 0 0 -0 0</pose>
        </inertial>
        <collision name='collision'>
          <geometry>
            <box>
              <size>0.5 0.4 0.3</size>
            </box>
          </geometry>
          <surface>
            <friction>
              <ode>
                <mu>1</mu>
                <mu2>1</mu2>
              </ode>
              <torsional>
                <ode/>
              </torsional>
            </friction>
            <contact>
              <ode>
                <kp>1e+07</kp>
                <kd>1</kd>
                <min_depth>0.001</min_depth>
                <max_vel>0.1</max_vel>
              </ode>
            </contact>
            <bounce/>
          </surface>
          <max_contacts>10</max_contacts>
        </collision>
        <visual name='visual'>
          <pose>0 0 -0.15 0 -0 0</pose>
          <geometry>
            <mesh>
              <uri>model://cardboard_box/meshes/cardboard_box.dae</uri>
              <scale>1.25932 1.00745 0.755591</scale>
            </mesh>
          </geometry>
        </visual>
        <self_collide>0</self_collide>
        <enable_wind>0</enable_wind>
        <kinematic>0</kinematic>
      </link>
    </model>
    <model name='cardboard_box_1'>
      <pose>1.51983 -0.988403 0.15 0 -0 0</pose>
      <link name='link'>
        <inertial>
          <mass>2</mass>
          <inertia>
            <ixx>0.0416667</ixx>
            <ixy>0</ixy>
            <ixz>0</ixz>
            <iyy>0.0566667</iyy>
            <iyz>0</iyz>
            <izz>0.0683333</izz>
          </inertia>
          <pose>0 0 0 0 -0 0</pose>
        </inertial>
        <collision name='collision'>
          <geometry>
            <box>
              <size>0.5 0.4 0.3</size>
            </box>
          </geometry>
          <surface>
            <friction>
              <ode>
                <mu>1</mu>
                <mu2>1</mu2>
              </ode>
              <torsional>
                <ode/>
              </torsional>
            </friction>
            <contact>
              <ode>
                <kp>1e+07</kp>
                <kd>1</kd>
                <min_depth>0.001</min_depth>
                <max_vel>0.1</max_vel>
              </ode>
            </contact>
            <bounce/>
          </surface>
          <max_contacts>10</max_contacts>
        </collision>
        <visual name='visual'>
          <pose>0 0 -0.15 0 -0 0</pose>
          <geometry>
            <mesh>
              <uri>model://cardboard_box/meshes/cardboard_box.dae</uri>
              <scale>1.25932 1.00745 0.755591</scale>
            </mesh>
          </geometry>
        </visual>
        <self_collide>0</self_collide>
        <enable_wind>0</enable_wind>
        <kinematic>0</kinematic>
      </link>
    </model>
    <state world_name='default'>
      <sim_time>83 988000000</sim_time>
      <real_time>84 539166357</real_time>
      <wall_time>1747328022 803205818</wall_time>
      <iterations>83988</iterations>
      <model name='cardboard_box'>
        <pose>0.24722 0.899305 0.149 -0 -0 -0</pose>
        <scale>1 1 1</scale>
        <link name='link'>
          <pose>0.24722 0.899305 0.149 -0 -0 -0</pose>
          <velocity>0 0 0 0 -0 0</velocity>
          <acceleration>0 -1.9e-05 0 0.000128 2e-06 0</acceleration>
          <wrench>1e-06 -3.8e-05 1e-06 0 -0 0</wrench>
        </link>
      </model>
      <model name='cardboard_box_0'>
        <pose>0.202515 -1.18824 0.149021 2e-06 -2e-06 -0</pose>
        <scale>1 1 1</scale>
        <link name='link'>
          <pose>0.202515 -1.18824 0.149021 2e-06 -2e-06 -0</pose>
          <velocity>0 0 0 0 -0 0</velocity>
          <acceleration>-0 -1.1e-05 -0 7.6e-05 -1e-06 0</acceleration>
          <wrench>-0 -2.3e-05 -1e-06 0 -0 0</wrench>
        </link>
      </model>
      <model name='cardboard_box_1'>
        <pose>1.51983 -0.988403 0.14951 2e-06 -2e-06 -0</pose>
        <scale>1 1 1</scale>
        <link name='link'>
          <pose>1.51983 -0.988403 0.14951 2e-06 -2e-06 -0</pose>
          <velocity>0 0 0 0 -0 0</velocity>
          <acceleration>0 0 0 0 -0 0</acceleration>
          <wrench>0 0 0 0 -0 0</wrench>
        </link>
      </model>
      <model name='ground_plane'>
        <pose>0 0 0 0 -0 0</pose>
        <scale>1 1 1</scale>
        <link name='link'>
          <pose>0 0 0 0 -0 0</pose>
          <velocity>0 0 0 0 -0 0</velocity>
          <acceleration>0 0 0 0 -0 0</acceleration>
          <wrench>0 0 0 0 -0 0</wrench>
        </link>
      </model>
      <model name='my_bot'>
        <pose>0.194258 -0.050622 0.022494 0.002806 -0.001792 -0.070132</pose>
        <scale>1 1 1</scale>
        <link name='base_footprint'>
          <pose>0.194258 -0.050622 0.022494 0.002806 -0.001792 -0.070132</pose>
          <velocity>0.000111 0.003145 -0.009883 -0.037299 0.037351 7.7e-05</velocity>
          <acceleration>-0.005345 -0.351122 -4.39375 3.12573 0.524619 -0.808892</acceleration>
          <wrench>-0.132235 -8.68676 -108.701 0 -0 0</wrench>
        </link>
        <link name='fr_left_steer_link'>
          <pose>0.317701 0.005773 0.049058 0.002762 -0.001728 -0.070636</pose>
          <velocity>0.004559 -0.001211 0.014377 -0.020685 0.079009 0.038084</velocity>
          <acceleration>-5.60917 -1.63989 19.1906 -1.90843 -1.10972 1.59465</acceleration>
          <wrench>-0.056092 -0.016399 0.191906 0 -0 0</wrench>
        </link>
        <link name='fr_left_wheel_link'>
          <pose>0.319562 0.028542 0.03503 0.003099 -0.466263 -0.082077</pose>
          <velocity>0.001688 -5e-06 0.006397 0.001063 0.05916 0.035335</velocity>
          <acceleration>-4.0447 -1.26223 12.7584 0.363453 -0.009789 3.0047</acceleration>
          <wrench>-12.1341 -3.78669 38.2754 0 -0 0</wrench>
        </link>
        <link name='fr_right_steer_link'>
          <pose>0.308522 -0.123838 0.047325 0.000781 -0.002309 -0.070664</pose>
          <velocity>0.008657 -0.004496 0.015513 0.074361 0.118699 -0.122997</velocity>
          <acceleration>-9.30062 1.88133 68.8782 0.844931 -1.26568 2.38496</acceleration>
          <wrench>-0.093006 0.018813 0.688782 0 -0 0</wrench>
        </link>
        <link name='fr_right_wheel_link'>
          <pose>0.30693 -0.143325 0.035011 3.14043 0.5604 3.05715</pose>
          <velocity>0.00394 -0.000915 0.010243 0.023346 0.082495 -0.111281</velocity>
          <acceleration>-5.31184 1.57692 52.8629 1.94531 -0.648508 3.01079</acceleration>
          <wrench>-15.9355 4.73076 158.589 0 -0 0</wrench>
        </link>
        <link name='re_left_wheel_link'>
          <pose>0.084352 0.041521 0.035022 3.13343 -1.2191 3.07912</pose>
          <velocity>0.000528 0.003495 -0.009247 2.97494 -1.34444 3.13644</velocity>
          <acceleration>-0.009209 0.295166 -9.22067 -1.32479 -1.06138 0.741018</acceleration>
          <wrench>-0.027627 0.885498 -27.662 0 -0 0</wrench>
        </link>
        <link name='re_right_wheel_link'>
          <pose>0.072546 -0.126565 0.034549 0.002809 0.020282 -0.07007</pose>
          <velocity>0.000566 0.003594 -0.002516 2.96929 -1.25692 3.13616</velocity>
          <acceleration>-0.152852 0.254724 -2.2016 1.9907 1.1028 -0.115104</acceleration>
          <wrench>-0.458556 0.764173 -6.6048 0 -0 0</wrench>
        </link>
        <link name='virtual_steer_link'>
          <pose>-0.124955 -0.028199 0.02192 0.000134 -0.001791 -0.070132</pose>
          <velocity>8.6e-05 0.003106 0.001195 0.002432 0.034619 0.000151</velocity>
          <acceleration>0.019654 -0.141615 -7.95712 0 -0 0</acceleration>
          <wrench>2e-05 -0.000142 -0.007957 0 -0 0</wrench>
        </link>
      </model>
      <light name='sun'>
        <pose>0 0 10 0 -0 0</pose>
      </light>
    </state>
    <gui fullscreen='0'>
      <camera name='user_camera'>
        <pose>3.82604 -3.8954 4.0145 0 0.755643 2.3402</pose>
        <view_controller>orbit</view_controller>
        <projection_type>perspective</projection_type>
      </camera>
    </gui>
  </world>
</sdf>
